<sdf version='1.6'>
  <world name='default'>
    <model name='ground_plane'>
      <static>1</static>
      <link name='link'>
        <collision name='collision'>
          <geometry>
            <plane>
              <normal>0 0 1</normal>
              <size>100 100</size>
            </plane>
          </geometry>
          <surface>
            <friction>
              <ode>
                <mu>100</mu>
                <mu2>50</mu2>
              </ode>
              <torsional>
                <ode/>
              </torsional>
            </friction>
            <contact>
              <ode/>
            </contact>
            <bounce/>
          </surface>
          <max_contacts>10</max_contacts>
        </collision>
        <visual name='visual'>
          <cast_shadows>0</cast_shadows>
          <geometry>
            <plane>
              <normal>0 0 1</normal>
              <size>100 100</size>
            </plane>
          </geometry>
          <material>
            <script>
              <uri>file://media/materials/scripts/gazebo.material</uri>
              <name>Gazebo/Grey</name>
            </script>
          </material>
        </visual>
        <self_collide>0</self_collide>
        <kinematic>0</kinematic>
      </link>
    </model>
    <gui fullscreen='0'>
      <camera name='user_camera'>
        <pose frame=''>5.3361 -3.96453 5.79084 0 0.575642 2.32582</pose>
        <view_controller>orbit</view_controller>
        <projection_type>perspective</projection_type>
      </camera>
    </gui>
    <model name='human'>
      <pose frame=''>-0.09 1.29 -1.3 0 -0 0</pose>
      <static>1</static>
      <link name='body'>
        <visual name='visual'>
          <geometry>
            <mesh>
              <uri>/home/ubuntu/Desktop/catkin_ws/src/autonomous_eating/models/human1/meshes/human1.dae</uri>
              <scale>1 1 1</scale>
            </mesh>
          </geometry>
        </visual>
        <self_collide>0</self_collide>
        <kinematic>0</kinematic>
      </link>
    </model>
    <model name='table'>
      <static>1</static>
      <link name='table'>
        <collision name='surface'>
          <pose frame=''>0 0 1 0 -0 0</pose>
          <geometry>
            <box>
              <size>1.5 0.8 0.03</size>
            </box>
          </geometry>
          <surface>
            <friction>
              <ode>
                <mu>0.6</mu>
                <mu2>0.6</mu2>
              </ode>
              <torsional>
                <ode/>
              </torsional>
            </friction>
            <contact>
              <ode/>
            </contact>
            <bounce/>
          </surface>
          <max_contacts>10</max_contacts>
        </collision>
        <visual name='visual1'>
          <pose frame=''>0 0 1 0 -0 0</pose>
          <geometry>
            <box>
              <size>1.5 0.8 0.03</size>
            </box>
          </geometry>
          <material>
            <script>
              <uri>file://media/materials/scripts/gazebo.material</uri>
              <name>Gazebo/Wood</name>
            </script>
          </material>
        </visual>
        <collision name='front_left_leg'>
          <pose frame=''>0.68 0.38 0.5 0 -0 0</pose>
          <geometry>
            <cylinder>
              <radius>0.02</radius>
              <length>1</length>
            </cylinder>
          </geometry>
          <max_contacts>10</max_contacts>
          <surface>
            <contact>
              <ode/>
            </contact>
            <bounce/>
            <friction>
              <torsional>
                <ode/>
              </torsional>
              <ode/>
            </friction>
          </surface>
        </collision>
        <visual name='front_left_leg'>
          <pose frame=''>0.68 0.38 0.5 0 -0 0</pose>
          <geometry>
            <cylinder>
              <radius>0.02</radius>
              <length>1</length>
            </cylinder>
          </geometry>
          <material>
            <script>
              <uri>file://media/materials/scripts/gazebo.material</uri>
              <name>Gazebo/Grey</name>
            </script>
          </material>
        </visual>
        <collision name='front_right_leg'>
          <pose frame=''>0.68 -0.38 0.5 0 -0 0</pose>
          <geometry>
            <cylinder>
              <radius>0.02</radius>
              <length>1</length>
            </cylinder>
          </geometry>
          <max_contacts>10</max_contacts>
          <surface>
            <contact>
              <ode/>
            </contact>
            <bounce/>
            <friction>
              <torsional>
                <ode/>
              </torsional>
              <ode/>
            </friction>
          </surface>
        </collision>
        <visual name='front_right_leg'>
          <pose frame=''>0.68 -0.38 0.5 0 -0 0</pose>
          <geometry>
            <cylinder>
              <radius>0.02</radius>
              <length>1</length>
            </cylinder>
          </geometry>
          <material>
            <script>
              <uri>file://media/materials/scripts/gazebo.material</uri>
              <name>Gazebo/Grey</name>
            </script>
          </material>
        </visual>
        <collision name='back_right_leg'>
          <pose frame=''>-0.68 -0.38 0.5 0 -0 0</pose>
          <geometry>
            <cylinder>
              <radius>0.02</radius>
              <length>1</length>
            </cylinder>
          </geometry>
          <max_contacts>10</max_contacts>
          <surface>
            <contact>
              <ode/>
            </contact>
            <bounce/>
            <friction>
              <torsional>
                <ode/>
              </torsional>
              <ode/>
            </friction>
          </surface>
        </collision>
        <visual name='back_right_leg'>
          <pose frame=''>-0.68 -0.38 0.5 0 -0 0</pose>
          <geometry>
            <cylinder>
              <radius>0.02</radius>
              <length>1</length>
            </cylinder>
          </geometry>
          <material>
            <script>
              <uri>file://media/materials/scripts/gazebo.material</uri>
              <name>Gazebo/Grey</name>
            </script>
          </material>
        </visual>
        <collision name='back_left_leg'>
          <pose frame=''>-0.68 0.38 0.5 0 -0 0</pose>
          <geometry>
            <cylinder>
              <radius>0.02</radius>
              <length>1</length>
            </cylinder>
          </geometry>
          <max_contacts>10</max_contacts>
          <surface>
            <contact>
              <ode/>
            </contact>
            <bounce/>
            <friction>
              <torsional>
                <ode/>
              </torsional>
              <ode/>
            </friction>
          </surface>
        </collision>
        <visual name='back_left_leg'>
          <pose frame=''>-0.68 0.38 0.5 0 -0 0</pose>
          <geometry>
            <cylinder>
              <radius>0.02</radius>
              <length>1</length>
            </cylinder>
          </geometry>
          <material>
            <script>
              <uri>file://media/materials/scripts/gazebo.material</uri>
              <name>Gazebo/Grey</name>
            </script>
          </material>
        </visual>
        <self_collide>0</self_collide>
        <kinematic>0</kinematic>
      </link>
      <pose frame=''>-0.08 0.78 -0.29 0 -0 0</pose>
    </model>
    <scene>
      <ambient>0.4 0.4 0.4 1</ambient>
      <background>0.25 0.25 0.25 1</background>
      <shadows>0</shadows>
    </scene>
    <light name='some_light' type='directional'>
      <diffuse>0.7 0.7 0.7 0</diffuse>
      <specular>1 1 1 0</specular>
      <direction>-1 -1 -1</direction>
    </light>
    <gravity>0 0 -9.8</gravity>
    <magnetic_field>6e-06 2.3e-05 -4.2e-05</magnetic_field>
    <atmosphere type='adiabatic'/>
    <physics name='default_physics' default='0' type='ode'>
      <max_step_size>0.001</max_step_size>
      <real_time_factor>1</real_time_factor>
      <real_time_update_rate>1000</real_time_update_rate>
    </physics>
    <spherical_coordinates>
      <surface_model>EARTH_WGS84</surface_model>
      <latitude_deg>0</latitude_deg>
      <longitude_deg>0</longitude_deg>
      <elevation>0</elevation>
      <heading_deg>0</heading_deg>
    </spherical_coordinates>
    <model name='j2n6s300'>
      <link name='root'>
        <pose frame=''>0.3 1.05 0.73 0 -0 0</pose>
        <inertial>
          <pose frame=''>0 0 0.1255 0 -0 0</pose>
          <mass>0.46784</mass>
          <inertia>
            <ixx>0.000951271</ixx>
            <ixy>0</ixy>
            <ixz>0</ixz>
            <iyy>0.000951271</iyy>
            <iyz>0</iyz>
            <izz>0.000374272</izz>
          </inertia>
        </inertial>
        <collision name='root_fixed_joint_lump__j2n6s300_link_base_collision'>
          <pose frame=''>0 0 0 0 -0 0</pose>
          <geometry>
            <mesh>
              <scale>1 1 1</scale>
              <uri>/home/ubuntu/Desktop/catkin_ws/src/kinova-ros/kinova_description/meshes/base.dae</uri>
            </mesh>
          </geometry>
          <max_contacts>10</max_contacts>
          <surface>
            <contact>
              <ode/>
            </contact>
            <bounce/>
            <friction>
              <torsional>
                <ode/>
              </torsional>
              <ode/>
            </friction>
          </surface>
        </collision>
        <visual name='root_fixed_joint_lump__j2n6s300_link_base_visual'>
          <pose frame=''>0 0 0 0 -0 0</pose>
          <geometry>
            <mesh>
              <scale>1 1 1</scale>
              <uri>/home/ubuntu/Desktop/catkin_ws/src/kinova-ros/kinova_description/meshes/base.dae</uri>
            </mesh>
          </geometry>
        </visual>
        <self_collide>0</self_collide>
        <kinematic>0</kinematic>
      </link>
      <joint name='connect_root_and_world' type='fixed'>
        <child>root</child>
        <parent>world</parent>
      </joint>
      <link name='j2n6s300_link_1'>
        <pose frame=''>0.3 1.05 0.90675 3.14159 -0 3.14159</pose>
        <inertial>
          <pose frame=''>0 -0.002 -0.0605 0 -0 0</pose>
          <mass>0.7477</mass>
          <inertia>
            <ixx>0.00152032</ixx>
            <ixy>0</ixy>
            <ixz>0</ixz>
            <iyy>0.00152032</iyy>
            <iyz>0</iyz>
            <izz>0.00059816</izz>
          </inertia>
        </inertial>
        <collision name='j2n6s300_link_1_collision'>
          <pose frame=''>0 0 0 0 -0 0</pose>
          <geometry>
            <mesh>
              <scale>1 1 1</scale>
              <uri>/home/ubuntu/Desktop/catkin_ws/src/kinova-ros/kinova_description/meshes/shoulder.dae</uri>
            </mesh>
          </geometry>
          <max_contacts>10</max_contacts>
          <surface>
            <contact>
              <ode/>
            </contact>
            <bounce/>
            <friction>
              <torsional>
                <ode/>
              </torsional>
              <ode/>
            </friction>
          </surface>
        </collision>
        <visual name='j2n6s300_link_1_visual'>
          <pose frame=''>0 0 0 0 -0 0</pose>
          <geometry>
            <mesh>
              <scale>1 1 1</scale>
              <uri>/home/ubuntu/Desktop/catkin_ws/src/kinova-ros/kinova_description/meshes/shoulder.dae</uri>
            </mesh>
          </geometry>
        </visual>
        <visual name='j2n6s300_link_1_visual_1'>
          <pose frame=''>0 0 0 0 -0 0</pose>
          <geometry>
            <mesh>
              <scale>1 1 1</scale>
              <uri>/home/ubuntu/Desktop/catkin_ws/src/kinova-ros/kinova_description/meshes/ring_big.dae</uri>
            </mesh>
          </geometry>
        </visual>
        <self_collide>0</self_collide>
        <kinematic>0</kinematic>
      </link>
      <joint name='j2n6s300_joint_1' type='revolute'>
        <child>j2n6s300_link_1</child>
        <parent>root</parent>
        <axis>
          <xyz>0 0 -1</xyz>
          <limit>
            <lower>-1e+16</lower>
            <upper>1e+16</upper>
          </limit>
          <dynamics>
            <damping>0</damping>
            <friction>0</friction>
            <spring_reference>0</spring_reference>
            <spring_stiffness>0</spring_stiffness>
          </dynamics>
          <use_parent_model_frame>1</use_parent_model_frame>
        </axis>
        <physics>
          <provide_feedback>1</provide_feedback>
          <ode>
            <provide_feedback>1</provide_feedback>
            <limit>
              <cfm>0</cfm>
              <erp>0.2</erp>
            </limit>
          </ode>
        </physics>
      </joint>
      <link name='j2n6s300_link_2'>
        <pose frame=''>0.3 1.0516 1.0255 1.5708 -0 0</pose>
        <inertial>
          <pose frame=''>0 -0.2065 -0.01 0 -0 0</pose>
          <mass>0.99</mass>
          <inertia>
            <ixx>0.0105022</ixx>
            <ixy>0</ixy>
            <ixz>0</ixz>
            <iyy>0.000792</iyy>
            <iyz>0</iyz>
            <izz>0.0105022</izz>
          </inertia>
        </inertial>
        <collision name='j2n6s300_link_2_collision'>
          <pose frame=''>0 0 0 0 -0 0</pose>
          <geometry>
            <mesh>
              <scale>1 1 1</scale>
              <uri>/home/ubuntu/Desktop/catkin_ws/src/kinova-ros/kinova_description/meshes/arm.dae</uri>
            </mesh>
          </geometry>
          <max_contacts>10</max_contacts>
          <surface>
            <contact>
              <ode/>
            </contact>
            <bounce/>
            <friction>
              <torsional>
                <ode/>
              </torsional>
              <ode/>
            </friction>
          </surface>
        </collision>
        <visual name='j2n6s300_link_2_visual'>
          <pose frame=''>0 0 0 0 -0 0</pose>
          <geometry>
            <mesh>
              <scale>1 1 1</scale>
              <uri>/home/ubuntu/Desktop/catkin_ws/src/kinova-ros/kinova_description/meshes/arm.dae</uri>
            </mesh>
          </geometry>
        </visual>
        <visual name='j2n6s300_link_2_visual_1'>
          <pose frame=''>0 0 0 0 -0 0</pose>
          <geometry>
            <mesh>
              <scale>1 1 1</scale>
              <uri>/home/ubuntu/Desktop/catkin_ws/src/kinova-ros/kinova_description/meshes/ring_big.dae</uri>
            </mesh>
          </geometry>
        </visual>
        <self_collide>0</self_collide>
        <kinematic>0</kinematic>
      </link>
      <joint name='j2n6s300_joint_2' type='revolute'>
        <child>j2n6s300_link_2</child>
        <parent>j2n6s300_link_1</parent>
        <axis>
          <xyz>0 -1 0</xyz>
          <limit>
            <lower>0.820305</lower>
            <upper>5.46288</upper>
            <effort>80</effort>
            <velocity>0.628319</velocity>
          </limit>
          <dynamics>
            <damping>0</damping>
            <friction>0</friction>
            <spring_reference>0</spring_reference>
            <spring_stiffness>0</spring_stiffness>
          </dynamics>
          <use_parent_model_frame>1</use_parent_model_frame>
        </axis>
        <physics>
          <provide_feedback>1</provide_feedback>
          <ode>
            <provide_feedback>1</provide_feedback>
            <limit>
              <cfm>0</cfm>
              <erp>0.2</erp>
            </limit>
          </ode>
        </physics>
      </joint>
      <link name='j2n6s300_link_3'>
        <pose frame=''>0.3 1.0516 0.6155 1.5708 -0 3.14159</pose>
        <inertial>
          <pose frame=''>0 0.081 -0.0086 0 -0 0</pose>
          <mass>0.6763</mass>
          <inertia>
            <ixx>0.00142022</ixx>
            <ixy>0</ixy>
            <ixz>0</ixz>
            <iyy>0.000304335</iyy>
            <iyz>0</iyz>
            <izz>0.00142022</izz>
          </inertia>
        </inertial>
        <collision name='j2n6s300_link_3_collision'>
          <pose frame=''>0 0 0 0 -0 0</pose>
          <geometry>
            <mesh>
              <scale>1 1 1</scale>
              <uri>/home/ubuntu/Desktop/catkin_ws/src/kinova-ros/kinova_description/meshes/forearm.dae</uri>
            </mesh>
          </geometry>
          <max_contacts>10</max_contacts>
          <surface>
            <contact>
              <ode/>
            </contact>
            <bounce/>
            <friction>
              <torsional>
                <ode/>
              </torsional>
              <ode/>
            </friction>
          </surface>
        </collision>
        <visual name='j2n6s300_link_3_visual'>
          <pose frame=''>0 0 0 0 -0 0</pose>
          <geometry>
            <mesh>
              <scale>1 1 1</scale>
              <uri>/home/ubuntu/Desktop/catkin_ws/src/kinova-ros/kinova_description/meshes/forearm.dae</uri>
            </mesh>
          </geometry>
        </visual>
        <visual name='j2n6s300_link_3_visual_1'>
          <pose frame=''>0 0 0 0 -0 0</pose>
          <geometry>
            <mesh>
              <scale>1 1 1</scale>
              <uri>/home/ubuntu/Desktop/catkin_ws/src/kinova-ros/kinova_description/meshes/ring_big.dae</uri>
            </mesh>
          </geometry>
        </visual>
        <self_collide>0</self_collide>
        <kinematic>0</kinematic>
      </link>
      <joint name='j2n6s300_joint_3' type='revolute'>
        <child>j2n6s300_link_3</child>
        <parent>j2n6s300_link_2</parent>
        <axis>
          <xyz>0 1 0</xyz>
          <limit>
            <lower>0.331613</lower>
            <upper>5.95157</upper>
            <effort>40</effort>
            <velocity>0.628319</velocity>
          </limit>
          <dynamics>
            <damping>0</damping>
            <friction>0</friction>
            <spring_reference>0</spring_reference>
            <spring_stiffness>0</spring_stiffness>
          </dynamics>
          <use_parent_model_frame>1</use_parent_model_frame>
        </axis>
        <physics>
          <provide_feedback>1</provide_feedback>
          <ode>
            <provide_feedback>1</provide_feedback>
            <limit>
              <cfm>0</cfm>
              <erp>0.2</erp>
            </limit>
          </ode>
        </physics>
      </joint>
      <link name='j2n6s300_link_4'>
        <pose frame=''>0.3 1.0402 0.8228 -3.14159 0 0</pose>
        <inertial>
          <pose frame=''>0 -0.037 -0.0642 0 -0 0</pose>
          <mass>0.426367</mass>
          <inertia>
            <ixx>7.73497e-05</ixx>
            <ixy>0</ixy>
            <ixz>0</ixz>
            <iyy>7.73497e-05</iyy>
            <iyz>0</iyz>
            <izz>0.0001428</izz>
          </inertia>
        </inertial>
        <collision name='j2n6s300_link_4_collision'>
          <pose frame=''>0 0 0 0 -0 0</pose>
          <geometry>
            <mesh>
              <scale>1 1 1</scale>
              <uri>/home/ubuntu/Desktop/catkin_ws/src/kinova-ros/kinova_description/meshes/wrist.dae</uri>
            </mesh>
          </geometry>
          <max_contacts>10</max_contacts>
          <surface>
            <contact>
              <ode/>
            </contact>
            <bounce/>
            <friction>
              <torsional>
                <ode/>
              </torsional>
              <ode/>
            </friction>
          </surface>
        </collision>
        <visual name='j2n6s300_link_4_visual'>
          <pose frame=''>0 0 0 0 -0 0</pose>
          <geometry>
            <mesh>
              <scale>1 1 1</scale>
              <uri>/home/ubuntu/Desktop/catkin_ws/src/kinova-ros/kinova_description/meshes/wrist.dae</uri>
            </mesh>
          </geometry>
        </visual>
        <visual name='j2n6s300_link_4_visual_1'>
          <pose frame=''>0 0 0 0 -0 0</pose>
          <geometry>
            <mesh>
              <scale>1 1 1</scale>
              <uri>/home/ubuntu/Desktop/catkin_ws/src/kinova-ros/kinova_description/meshes/ring_small.dae</uri>
            </mesh>
          </geometry>
        </visual>
        <self_collide>0</self_collide>
        <kinematic>0</kinematic>
      </link>
      <joint name='j2n6s300_joint_4' type='revolute'>
        <child>j2n6s300_link_4</child>
        <parent>j2n6s300_link_3</parent>
        <axis>
          <xyz>0 0 -1</xyz>
          <limit>
            <lower>-1e+16</lower>
            <upper>1e+16</upper>
          </limit>
          <dynamics>
            <damping>0</damping>
            <friction>0</friction>
            <spring_reference>0</spring_reference>
            <spring_stiffness>0</spring_stiffness>
          </dynamics>
          <use_parent_model_frame>1</use_parent_model_frame>
        </axis>
        <physics>
          <provide_feedback>1</provide_feedback>
          <ode>
            <provide_feedback>1</provide_feedback>
            <limit>
              <cfm>0</cfm>
              <erp>0.2</erp>
            </limit>
          </ode>
        </physics>
      </joint>
      <link name='j2n6s300_link_5'>
        <pose frame=''>0.3 1.07723 0.88694 -2.0944 -0 3.14159</pose>
        <inertial>
          <pose frame=''>0 -0.037 -0.0642 0 -0 0</pose>
          <mass>0.426367</mass>
          <inertia>
            <ixx>7.73497e-05</ixx>
            <ixy>0</ixy>
            <ixz>0</ixz>
            <iyy>7.73497e-05</iyy>
            <iyz>0</iyz>
            <izz>0.0001428</izz>
          </inertia>
        </inertial>
        <collision name='j2n6s300_link_5_collision'>
          <pose frame=''>0 0 0 0 -0 0</pose>
          <geometry>
            <mesh>
              <scale>1 1 1</scale>
              <uri>/home/ubuntu/Desktop/catkin_ws/src/kinova-ros/kinova_description/meshes/wrist.dae</uri>
            </mesh>
          </geometry>
          <max_contacts>10</max_contacts>
          <surface>
            <contact>
              <ode/>
            </contact>
            <bounce/>
            <friction>
              <torsional>
                <ode/>
              </torsional>
              <ode/>
            </friction>
          </surface>
        </collision>
        <visual name='j2n6s300_link_5_visual'>
          <pose frame=''>0 0 0 0 -0 0</pose>
          <geometry>
            <mesh>
              <scale>1 1 1</scale>
              <uri>/home/ubuntu/Desktop/catkin_ws/src/kinova-ros/kinova_description/meshes/wrist.dae</uri>
            </mesh>
          </geometry>
        </visual>
        <visual name='j2n6s300_link_5_visual_1'>
          <pose frame=''>0 0 0 0 -0 0</pose>
          <geometry>
            <mesh>
              <scale>1 1 1</scale>
              <uri>/home/ubuntu/Desktop/catkin_ws/src/kinova-ros/kinova_description/meshes/ring_small.dae</uri>
            </mesh>
          </geometry>
        </visual>
        <self_collide>0</self_collide>
        <kinematic>0</kinematic>
      </link>
      <joint name='j2n6s300_joint_5' type='revolute'>
        <child>j2n6s300_link_5</child>
        <parent>j2n6s300_link_4</parent>
        <axis>
          <xyz>0 -0.866025 -0.5</xyz>
          <limit>
            <lower>-1e+16</lower>
            <upper>1e+16</upper>
          </limit>
          <dynamics>
            <damping>0</damping>
            <friction>0</friction>
            <spring_reference>0</spring_reference>
            <spring_stiffness>0</spring_stiffness>
          </dynamics>
          <use_parent_model_frame>1</use_parent_model_frame>
        </axis>
        <physics>
          <provide_feedback>1</provide_feedback>
          <ode>
            <provide_feedback>1</provide_feedback>
            <limit>
              <cfm>0</cfm>
              <erp>0.2</erp>
            </limit>
          </ode>
        </physics>
      </joint>
      <link name='j2n6s300_link_6'>
        <pose frame=''>0.3 1.11426 0.951079 -3.14159 0 0</pose>
        <inertial>
          <pose frame=''>0 0 -0.06 0 -0 0</pose>
          <mass>0.99</mass>
          <inertia>
            <ixx>0.000434634</ixx>
            <ixy>0</ixy>
            <ixz>-8.19984e-11</ixz>
            <iyy>0.000347834</iyy>
            <iyz>0</iyz>
            <izz>0.00067268</izz>
          </inertia>
        </inertial>
        <collision name='j2n6s300_link_6_collision'>
          <pose frame=''>0 0 0 0 -0 0</pose>
          <geometry>
            <mesh>
              <scale>1 1 1</scale>
              <uri>/home/ubuntu/Desktop/catkin_ws/src/kinova-ros/kinova_description/meshes/hand_3finger.dae</uri>
            </mesh>
          </geometry>
          <max_contacts>10</max_contacts>
          <surface>
            <contact>
              <ode/>
            </contact>
            <bounce/>
            <friction>
              <torsional>
                <ode/>
              </torsional>
              <ode/>
            </friction>
          </surface>
        </collision>
        <collision name='j2n6s300_link_6_fixed_joint_lump__rs200_camera_collision_1'>
          <pose frame=''>0.1 0 0 0 1.57075 0</pose>
          <geometry>
            <box>
              <size>0.0078 0.13 0.0192</size>
            </box>
          </geometry>
          <surface>
            <contact>
              <ode>
                <kp>1e+13</kp>
                <kd>1</kd>
              </ode>
            </contact>
            <friction>
              <ode>
                <mu2>1</mu2>
                <fdir1>0 0 0</fdir1>
              </ode>
              <torsional>
                <ode/>
              </torsional>
            </friction>
            <bounce/>
          </surface>
          <max_contacts>10</max_contacts>
        </collision>
        <visual name='j2n6s300_link_6_visual'>
          <pose frame=''>0 0 0 0 -0 0</pose>
          <geometry>
            <mesh>
              <scale>1 1 1</scale>
              <uri>/home/ubuntu/Desktop/catkin_ws/src/kinova-ros/kinova_description/meshes/hand_3finger.dae</uri>
            </mesh>
          </geometry>
        </visual>
        <visual name='j2n6s300_link_6_visual_1'>
          <pose frame=''>0 0 0 0 -0 0</pose>
          <geometry>
            <mesh>
              <scale>1 1 1</scale>
              <uri>/home/ubuntu/Desktop/catkin_ws/src/kinova-ros/kinova_description/meshes/ring_small.dae</uri>
            </mesh>
          </geometry>
        </visual>
        <visual name='j2n6s300_link_6_fixed_joint_lump__rs200_camera_visual_2'>
          <pose frame=''>0.1 0 0 0 1.57075 0</pose>
          <geometry>
            <mesh>
              <scale>1 1 1</scale>
              <uri>/home/ubuntu/Desktop/catkin_ws/src/realsense_gazebo_plugin/models/realsense_camera/meshes/realsense.dae</uri>
            </mesh>
          </geometry>
          <material>
            <script>
              <uri>__default__</uri>
              <name>__default__</name>
            </script>
          </material>
        </visual>
        <gravity>1</gravity>
        <velocity_decay/>
        <self_collide>0</self_collide>
        <enable_wind>0</enable_wind>
        <kinematic>0</kinematic>
        <gravity>1</gravity>
        <sensor name='color' type='camera'>
          <camera name='rs200_camera'>
            <horizontal_fov>1.047</horizontal_fov>
            <image>
              <width>640</width>
              <height>480</height>
              <format>RGB_INT8</format>
            </image>
            <clip>
              <near>0.1</near>
              <far>100</far>
            </clip>
            <noise>
              <type>gaussian</type>
              <mean>0</mean>
              <stddev>0.007</stddev>
            </noise>
          </camera>
          <always_on>1</always_on>
          <update_rate>60</update_rate>
          <visualize>1</visualize>
          <pose frame=''>0.1 0 0 0 1.57075 0</pose>
        </sensor>
        <sensor name='ired1' type='camera'>
          <camera name='rs200_camera'>
            <horizontal_fov>1.047</horizontal_fov>
            <image>
              <width>640</width>
              <height>480</height>
              <format>L_INT8</format>
            </image>
            <clip>
              <near>0.1</near>
              <far>100</far>
            </clip>
            <noise>
              <type>gaussian</type>
              <mean>0</mean>
              <stddev>0.05</stddev>
            </noise>
          </camera>
          <always_on>1</always_on>
          <update_rate>60</update_rate>
          <visualize>0</visualize>
          <pose frame=''>0.1 0 0 0 1.57075 0</pose>
        </sensor>
        <sensor name='ired2' type='camera'>
          <camera name='rs200_camera'>
            <horizontal_fov>1.047</horizontal_fov>
            <image>
              <width>640</width>
              <height>480</height>
              <format>L_INT8</format>
            </image>
            <clip>
              <near>0.1</near>
              <far>100</far>
            </clip>
            <noise>
              <type>gaussian</type>
              <mean>0</mean>
              <stddev>0.05</stddev>
            </noise>
          </camera>
          <always_on>1</always_on>
          <update_rate>60</update_rate>
          <visualize>0</visualize>
          <pose frame=''>0.1 0 0 0 1.57075 0</pose>
        </sensor>
        <sensor name='depth' type='depth'>
          <camera name='rs200_camera'>
            <horizontal_fov>1.047</horizontal_fov>
            <image>
              <width>640</width>
              <height>480</height>
            </image>
            <clip>
              <near>0.1</near>
              <far>100</far>
            </clip>
            <noise>
              <type>gaussian</type>
              <mean>0</mean>
              <stddev>0.1</stddev>
            </noise>
          </camera>
          <always_on>1</always_on>
          <update_rate>60</update_rate>
          <visualize>0</visualize>
          <pose frame=''>0.1 0 0 0 1.57075 0</pose>
        </sensor>
      </link>
      <joint name='j2n6s300_joint_6' type='revolute'>
        <child>j2n6s300_link_6</child>
        <parent>j2n6s300_link_5</parent>
        <axis>
          <xyz>0 0 -1</xyz>
          <limit>
            <lower>-1e+16</lower>
            <upper>1e+16</upper>
          </limit>
          <dynamics>
            <damping>0</damping>
            <friction>0</friction>
            <spring_reference>0</spring_reference>
            <spring_stiffness>0</spring_stiffness>
          </dynamics>
          <use_parent_model_frame>1</use_parent_model_frame>
        </axis>
        <physics>
          <provide_feedback>1</provide_feedback>
          <ode>
            <provide_feedback>1</provide_feedback>
            <limit>
              <cfm>0</cfm>
              <erp>0.2</erp>
            </limit>
          </ode>
        </physics>
      </joint>
      <link name='j2n6s300_link_finger_1'>
        <pose frame=''>0.30279 1.083 1.06575 1.5708 -0.649262 -1.35961</pose>
        <inertial>
          <pose frame=''>0.022 0 0 0 -0 0</pose>
          <mass>0.01</mass>
          <inertia>
            <ixx>7.89997e-07</ixx>
            <ixy>0</ixy>
            <ixz>0</ixz>
            <iyy>7.89997e-07</iyy>
            <iyz>0</iyz>
            <izz>8e-08</izz>
          </inertia>
        </inertial>
        <collision name='j2n6s300_link_finger_1_collision'>
          <pose frame=''>0 0 0 0 -0 0</pose>
          <geometry>
            <mesh>
              <scale>1 1 1</scale>
              <uri>/home/ubuntu/Desktop/catkin_ws/src/kinova-ros/kinova_description/meshes/finger_proximal.dae</uri>
            </mesh>
          </geometry>
          <max_contacts>10</max_contacts>
          <surface>
            <contact>
              <ode/>
            </contact>
            <bounce/>
            <friction>
              <torsional>
                <ode/>
              </torsional>
              <ode/>
            </friction>
          </surface>
        </collision>
        <visual name='j2n6s300_link_finger_1_visual'>
          <pose frame=''>0 0 0 0 -0 0</pose>
          <geometry>
            <mesh>
              <scale>1 1 1</scale>
              <uri>/home/ubuntu/Desktop/catkin_ws/src/kinova-ros/kinova_description/meshes/finger_proximal.dae</uri>
            </mesh>
          </geometry>
        </visual>
        <self_collide>0</self_collide>
        <kinematic>0</kinematic>
      </link>
      <joint name='j2n6s300_joint_finger_1' type='revolute'>
        <child>j2n6s300_link_finger_1</child>
        <parent>j2n6s300_link_6</parent>
        <axis>
          <xyz>-0.977783 -0.209619 0</xyz>
          <limit>
            <lower>0</lower>
            <upper>1.51</upper>
            <effort>2</effort>
            <velocity>1</velocity>
          </limit>
          <dynamics>
            <spring_reference>0</spring_reference>
            <spring_stiffness>0</spring_stiffness>
          </dynamics>
          <use_parent_model_frame>1</use_parent_model_frame>
        </axis>
      </joint>
      <link name='j2n6s300_link_finger_tip_1'>
        <pose frame=''>0.310517 1.04696 1.08996 1.5708 -0.649262 -1.35961</pose>
        <inertial>
          <pose frame=''>0.022 0 0 0 -0 0</pose>
          <mass>0.01</mass>
          <inertia>
            <ixx>7.89997e-07</ixx>
            <ixy>0</ixy>
            <ixz>0</ixz>
            <iyy>7.89997e-07</iyy>
            <iyz>0</iyz>
            <izz>8e-08</izz>
          </inertia>
        </inertial>
        <collision name='j2n6s300_link_finger_tip_1_collision'>
          <pose frame=''>0 0 0 0 -0 0</pose>
          <geometry>
            <mesh>
              <scale>1 1 1</scale>
              <uri>/home/ubuntu/Desktop/catkin_ws/src/kinova-ros/kinova_description/meshes/finger_distal.dae</uri>
            </mesh>
          </geometry>
          <max_contacts>10</max_contacts>
          <surface>
            <contact>
              <ode/>
            </contact>
            <bounce/>
            <friction>
              <torsional>
                <ode/>
              </torsional>
              <ode/>
            </friction>
          </surface>
        </collision>
        <visual name='j2n6s300_link_finger_tip_1_visual'>
          <pose frame=''>0 0 0 0 -0 0</pose>
          <geometry>
            <mesh>
              <scale>1 1 1</scale>
              <uri>/home/ubuntu/Desktop/catkin_ws/src/kinova-ros/kinova_description/meshes/finger_distal.dae</uri>
            </mesh>
          </geometry>
        </visual>
        <self_collide>0</self_collide>
        <kinematic>0</kinematic>
      </link>
      <joint name='j2n6s300_joint_finger_tip_1' type='revolute'>
        <child>j2n6s300_link_finger_tip_1</child>
        <parent>j2n6s300_link_finger_1</parent>
        <axis>
          <xyz>-0.977783 -0.209619 0</xyz>
          <limit>
            <lower>0</lower>
            <upper>2</upper>
            <effort>2</effort>
            <velocity>1</velocity>
          </limit>
          <dynamics>
            <spring_reference>0</spring_reference>
            <spring_stiffness>0</spring_stiffness>
          </dynamics>
          <use_parent_model_frame>1</use_parent_model_frame>
        </axis>
      </joint>
      <link name='j2n6s300_link_finger_2'>
        <pose frame=''>0.32226 1.14133 1.0659 1.5708 -0.649262 1.38614</pose>
        <inertial>
          <pose frame=''>0.022 0 0 0 -0 0</pose>
          <mass>0.01</mass>
          <inertia>
            <ixx>7.89997e-07</ixx>
            <ixy>0</ixy>
            <ixz>0</ixz>
            <iyy>7.89997e-07</iyy>
            <iyz>0</iyz>
            <izz>8e-08</izz>
          </inertia>
        </inertial>
        <collision name='j2n6s300_link_finger_2_collision'>
          <pose frame=''>0 0 0 0 -0 0</pose>
          <geometry>
            <mesh>
              <scale>1 1 1</scale>
              <uri>/home/ubuntu/Desktop/catkin_ws/src/kinova-ros/kinova_description/meshes/finger_proximal.dae</uri>
            </mesh>
          </geometry>
          <max_contacts>10</max_contacts>
          <surface>
            <contact>
              <ode/>
            </contact>
            <bounce/>
            <friction>
              <torsional>
                <ode/>
              </torsional>
              <ode/>
            </friction>
          </surface>
        </collision>
        <visual name='j2n6s300_link_finger_2_visual'>
          <pose frame=''>0 0 0 0 -0 0</pose>
          <geometry>
            <mesh>
              <scale>1 1 1</scale>
              <uri>/home/ubuntu/Desktop/catkin_ws/src/kinova-ros/kinova_description/meshes/finger_proximal.dae</uri>
            </mesh>
          </geometry>
        </visual>
        <self_collide>0</self_collide>
        <kinematic>0</kinematic>
      </link>
      <joint name='j2n6s300_joint_finger_2' type='revolute'>
        <child>j2n6s300_link_finger_2</child>
        <parent>j2n6s300_link_6</parent>
        <axis>
          <xyz>0.983 -0.183608 0</xyz>
          <limit>
            <lower>0</lower>
            <upper>1.51</upper>
            <effort>2</effort>
            <velocity>1</velocity>
          </limit>
          <dynamics>
            <spring_reference>0</spring_reference>
            <spring_stiffness>0</spring_stiffness>
          </dynamics>
          <use_parent_model_frame>1</use_parent_model_frame>
        </axis>
      </joint>
      <link name='j2n6s300_link_finger_tip_2'>
        <pose frame=''>0.329028 1.17757 1.09011 1.5708 -0.649262 1.38614</pose>
        <inertial>
          <pose frame=''>0.022 0 0 0 -0 0</pose>
          <mass>0.01</mass>
          <inertia>
            <ixx>7.89997e-07</ixx>
            <ixy>0</ixy>
            <ixz>0</ixz>
            <iyy>7.89997e-07</iyy>
            <iyz>0</iyz>
            <izz>8e-08</izz>
          </inertia>
        </inertial>
        <collision name='j2n6s300_link_finger_tip_2_collision'>
          <pose frame=''>0 0 0 0 -0 0</pose>
          <geometry>
            <mesh>
              <scale>1 1 1</scale>
              <uri>/home/ubuntu/Desktop/catkin_ws/src/kinova-ros/kinova_description/meshes/finger_distal.dae</uri>
            </mesh>
          </geometry>
          <max_contacts>10</max_contacts>
          <surface>
            <contact>
              <ode/>
            </contact>
            <bounce/>
            <friction>
              <torsional>
                <ode/>
              </torsional>
              <ode/>
            </friction>
          </surface>
        </collision>
        <visual name='j2n6s300_link_finger_tip_2_visual'>
          <pose frame=''>0 0 0 0 -0 0</pose>
          <geometry>
            <mesh>
              <scale>1 1 1</scale>
              <uri>/home/ubuntu/Desktop/catkin_ws/src/kinova-ros/kinova_description/meshes/finger_distal.dae</uri>
            </mesh>
          </geometry>
        </visual>
        <self_collide>0</self_collide>
        <kinematic>0</kinematic>
      </link>
      <joint name='j2n6s300_joint_finger_tip_2' type='revolute'>
        <child>j2n6s300_link_finger_tip_2</child>
        <parent>j2n6s300_link_finger_2</parent>
        <axis>
          <xyz>0.983 -0.183608 0</xyz>
          <limit>
            <lower>0</lower>
            <upper>2</upper>
            <effort>2</effort>
            <velocity>1</velocity>
          </limit>
          <dynamics>
            <spring_reference>0</spring_reference>
            <spring_stiffness>0</spring_stiffness>
          </dynamics>
          <use_parent_model_frame>1</use_parent_model_frame>
        </axis>
      </joint>
      <link name='j2n6s300_link_finger_3'>
        <pose frame=''>0.27774 1.14133 1.0659 1.5708 -0.649262 1.75545</pose>
        <inertial>
          <pose frame=''>0.022 0 0 0 -0 0</pose>
          <mass>0.01</mass>
          <inertia>
            <ixx>7.89997e-07</ixx>
            <ixy>0</ixy>
            <ixz>0</ixz>
            <iyy>7.89997e-07</iyy>
            <iyz>0</iyz>
            <izz>8e-08</izz>
          </inertia>
        </inertial>
        <collision name='j2n6s300_link_finger_3_collision'>
          <pose frame=''>0 0 0 0 -0 0</pose>
          <geometry>
            <mesh>
              <scale>1 1 1</scale>
              <uri>/home/ubuntu/Desktop/catkin_ws/src/kinova-ros/kinova_description/meshes/finger_proximal.dae</uri>
            </mesh>
          </geometry>
          <max_contacts>10</max_contacts>
          <surface>
            <contact>
              <ode/>
            </contact>
            <bounce/>
            <friction>
              <torsional>
                <ode/>
              </torsional>
              <ode/>
            </friction>
          </surface>
        </collision>
        <visual name='j2n6s300_link_finger_3_visual'>
          <pose frame=''>0 0 0 0 -0 0</pose>
          <geometry>
            <mesh>
              <scale>1 1 1</scale>
              <uri>/home/ubuntu/Desktop/catkin_ws/src/kinova-ros/kinova_description/meshes/finger_proximal.dae</uri>
            </mesh>
          </geometry>
        </visual>
        <self_collide>0</self_collide>
        <kinematic>0</kinematic>
      </link>
      <joint name='j2n6s300_joint_finger_3' type='revolute'>
        <child>j2n6s300_link_finger_3</child>
        <parent>j2n6s300_link_6</parent>
        <axis>
          <xyz>0.983 0.183608 0</xyz>
          <limit>
            <lower>0</lower>
            <upper>1.51</upper>
            <effort>2</effort>
            <velocity>1</velocity>
          </limit>
          <dynamics>
            <spring_reference>0</spring_reference>
            <spring_stiffness>0</spring_stiffness>
          </dynamics>
          <use_parent_model_frame>1</use_parent_model_frame>
        </axis>
      </joint>
      <link name='j2n6s300_link_finger_tip_3'>
        <pose frame=''>0.270972 1.17757 1.09011 1.5708 -0.649262 1.75545</pose>
        <inertial>
          <pose frame=''>0.022 0 0 0 -0 0</pose>
          <mass>0.01</mass>
          <inertia>
            <ixx>7.89997e-07</ixx>
            <ixy>0</ixy>
            <ixz>0</ixz>
            <iyy>7.89997e-07</iyy>
            <iyz>0</iyz>
            <izz>8e-08</izz>
          </inertia>
        </inertial>
        <collision name='j2n6s300_link_finger_tip_3_collision'>
          <pose frame=''>0 0 0 0 -0 0</pose>
          <geometry>
            <mesh>
              <scale>1 1 1</scale>
              <uri>/home/ubuntu/Desktop/catkin_ws/src/kinova-ros/kinova_description/meshes/finger_distal.dae</uri>
            </mesh>
          </geometry>
          <max_contacts>10</max_contacts>
          <surface>
            <contact>
              <ode/>
            </contact>
            <bounce/>
            <friction>
              <torsional>
                <ode/>
              </torsional>
              <ode/>
            </friction>
          </surface>
        </collision>
        <visual name='j2n6s300_link_finger_tip_3_visual'>
          <pose frame=''>0 0 0 0 -0 0</pose>
          <geometry>
            <mesh>
              <scale>1 1 1</scale>
              <uri>/home/ubuntu/Desktop/catkin_ws/src/kinova-ros/kinova_description/meshes/finger_distal.dae</uri>
            </mesh>
          </geometry>
        </visual>
        <self_collide>0</self_collide>
        <kinematic>0</kinematic>
      </link>
      <joint name='j2n6s300_joint_finger_tip_3' type='revolute'>
        <child>j2n6s300_link_finger_tip_3</child>
        <parent>j2n6s300_link_finger_3</parent>
        <axis>
          <xyz>0.983 0.183608 0</xyz>
          <limit>
            <lower>0</lower>
            <upper>2</upper>
            <effort>2</effort>
            <velocity>1</velocity>
          </limit>
          <dynamics>
            <spring_reference>0</spring_reference>
            <spring_stiffness>0</spring_stiffness>
          </dynamics>
          <use_parent_model_frame>1</use_parent_model_frame>
        </axis>
      </joint>
      <plugin name='gazebo_ros_control' filename='libgazebo_ros_control.so'>
        <robotNamespace>j2n6s300</robotNamespace>
        <robotSimType>gazebo_ros_control/DefaultRobotHWSim</robotSimType>
        <legacyModeNS>true</legacyModeNS>
      </plugin>
      <plugin name='ft_sensor' filename='libgazebo_ros_ft_sensor.so'>
        <updateRate>30.0</updateRate>
        <topicName>j2n6s300_joint_1_ft_sensor_topic</topicName>
        <jointName>j2n6s300_joint_1</jointName>
        <robotNamespace>/</robotNamespace>
      </plugin>
      <plugin name='ft_sensor' filename='libgazebo_ros_ft_sensor.so'>
        <updateRate>30.0</updateRate>
        <topicName>j2n6s300_joint_2_ft_sensor_topic</topicName>
        <jointName>j2n6s300_joint_2</jointName>
        <robotNamespace>/</robotNamespace>
      </plugin>
      <plugin name='ft_sensor' filename='libgazebo_ros_ft_sensor.so'>
        <updateRate>30.0</updateRate>
        <topicName>j2n6s300_joint_3_ft_sensor_topic</topicName>
        <jointName>j2n6s300_joint_3</jointName>
        <robotNamespace>/</robotNamespace>
      </plugin>
      <plugin name='ft_sensor' filename='libgazebo_ros_ft_sensor.so'>
        <updateRate>30.0</updateRate>
        <topicName>j2n6s300_joint_4_ft_sensor_topic</topicName>
        <jointName>j2n6s300_joint_4</jointName>
        <robotNamespace>/</robotNamespace>
      </plugin>
      <plugin name='ft_sensor' filename='libgazebo_ros_ft_sensor.so'>
        <updateRate>30.0</updateRate>
        <topicName>j2n6s300_joint_5_ft_sensor_topic</topicName>
        <jointName>j2n6s300_joint_5</jointName>
        <robotNamespace>/</robotNamespace>
      </plugin>
      <plugin name='ft_sensor' filename='libgazebo_ros_ft_sensor.so'>
        <updateRate>30.0</updateRate>
        <topicName>j2n6s300_joint_6_ft_sensor_topic</topicName>
        <jointName>j2n6s300_joint_6</jointName>
        <robotNamespace>/</robotNamespace>
      </plugin>
      <static>0</static>
      <plugin name='r200' filename='librealsense_gazebo_plugin.so'>
        <prefix/>
        <robotNamespace>/</robotNamespace>
      </plugin>
      <pose frame=''>0 0 0 0 -0 0</pose>
    </model>
    <model name='home'>
      <pose frame=''>0.349793 0.122852 0 0 -0 0</pose>
      <link name='Stairs_0'>
        <visual name='Stairs_0_Visual_0'>
          <pose frame=''>2.45797 -0.622751 0.083333 0 -0 0</pose>
          <geometry>
            <box>
              <size>1 0.233333 0.166667</size>
            </box>
          </geometry>
          <material>
            <script>
              <uri>file://media/materials/scripts/gazebo.material</uri>
              <name>Gazebo/Grey</name>
            </script>
            <ambient>1 1 1 1</ambient>
          </material>
          <meta>
            <layer>0</layer>
          </meta>
        </visual>
        <collision name='Stairs_0_Collision_0'>
          <geometry>
            <box>
              <size>1 0.233333 0.166667</size>
            </box>
          </geometry>
          <pose frame=''>2.45797 -0.622751 0.083333 0 -0 0</pose>
          <max_contacts>10</max_contacts>
          <surface>
            <contact>
              <ode/>
            </contact>
            <bounce/>
            <friction>
              <torsional>
                <ode/>
              </torsional>
              <ode/>
            </friction>
          </surface>
        </collision>
        <visual name='Stairs_0_Visual_1'>
          <pose frame=''>2.45797 -0.856085 0.25 0 -0 0</pose>
          <geometry>
            <box>
              <size>1 0.233333 0.166667</size>
            </box>
          </geometry>
          <material>
            <script>
              <uri>file://media/materials/scripts/gazebo.material</uri>
              <name>Gazebo/Grey</name>
            </script>
            <ambient>1 1 1 1</ambient>
          </material>
          <meta>
            <layer>0</layer>
          </meta>
        </visual>
        <collision name='Stairs_0_Collision_1'>
          <geometry>
            <box>
              <size>1 0.233333 0.166667</size>
            </box>
          </geometry>
          <pose frame=''>2.45797 -0.856085 0.25 0 -0 0</pose>
          <max_contacts>10</max_contacts>
          <surface>
            <contact>
              <ode/>
            </contact>
            <bounce/>
            <friction>
              <torsional>
                <ode/>
              </torsional>
              <ode/>
            </friction>
          </surface>
        </collision>
        <visual name='Stairs_0_Visual_2'>
          <pose frame=''>2.45797 -1.08942 0.416667 0 -0 0</pose>
          <geometry>
            <box>
              <size>1 0.233333 0.166667</size>
            </box>
          </geometry>
          <material>
            <script>
              <uri>file://media/materials/scripts/gazebo.material</uri>
              <name>Gazebo/Grey</name>
            </script>
            <ambient>1 1 1 1</ambient>
          </material>
          <meta>
            <layer>0</layer>
          </meta>
        </visual>
        <collision name='Stairs_0_Collision_2'>
          <geometry>
            <box>
              <size>1 0.233333 0.166667</size>
            </box>
          </geometry>
          <pose frame=''>2.45797 -1.08942 0.416667 0 -0 0</pose>
          <max_contacts>10</max_contacts>
          <surface>
            <contact>
              <ode/>
            </contact>
            <bounce/>
            <friction>
              <torsional>
                <ode/>
              </torsional>
              <ode/>
            </friction>
          </surface>
        </collision>
        <visual name='Stairs_0_Visual_3'>
          <pose frame=''>2.45797 -1.32275 0.583333 0 -0 0</pose>
          <geometry>
            <box>
              <size>1 0.233333 0.166667</size>
            </box>
          </geometry>
          <material>
            <script>
              <uri>file://media/materials/scripts/gazebo.material</uri>
              <name>Gazebo/Grey</name>
            </script>
            <ambient>1 1 1 1</ambient>
          </material>
          <meta>
            <layer>0</layer>
          </meta>
        </visual>
        <collision name='Stairs_0_Collision_3'>
          <geometry>
            <box>
              <size>1 0.233333 0.166667</size>
            </box>
          </geometry>
          <pose frame=''>2.45797 -1.32275 0.583333 0 -0 0</pose>
          <max_contacts>10</max_contacts>
          <surface>
            <contact>
              <ode/>
            </contact>
            <bounce/>
            <friction>
              <torsional>
                <ode/>
              </torsional>
              <ode/>
            </friction>
          </surface>
        </collision>
        <visual name='Stairs_0_Visual_4'>
          <pose frame=''>2.45797 -1.55608 0.75 0 -0 0</pose>
          <geometry>
            <box>
              <size>1 0.233333 0.166667</size>
            </box>
          </geometry>
          <material>
            <script>
              <uri>file://media/materials/scripts/gazebo.material</uri>
              <name>Gazebo/Grey</name>
            </script>
            <ambient>1 1 1 1</ambient>
          </material>
          <meta>
            <layer>0</layer>
          </meta>
        </visual>
        <collision name='Stairs_0_Collision_4'>
          <geometry>
            <box>
              <size>1 0.233333 0.166667</size>
            </box>
          </geometry>
          <pose frame=''>2.45797 -1.55608 0.75 0 -0 0</pose>
          <max_contacts>10</max_contacts>
          <surface>
            <contact>
              <ode/>
            </contact>
            <bounce/>
            <friction>
              <torsional>
                <ode/>
              </torsional>
              <ode/>
            </friction>
          </surface>
        </collision>
        <visual name='Stairs_0_Visual_5'>
          <pose frame=''>2.45797 -1.78942 0.916667 0 -0 0</pose>
          <geometry>
            <box>
              <size>1 0.233333 0.166667</size>
            </box>
          </geometry>
          <material>
            <script>
              <uri>file://media/materials/scripts/gazebo.material</uri>
              <name>Gazebo/Grey</name>
            </script>
            <ambient>1 1 1 1</ambient>
          </material>
          <meta>
            <layer>0</layer>
          </meta>
        </visual>
        <collision name='Stairs_0_Collision_5'>
          <geometry>
            <box>
              <size>1 0.233333 0.166667</size>
            </box>
          </geometry>
          <pose frame=''>2.45797 -1.78942 0.916667 0 -0 0</pose>
          <max_contacts>10</max_contacts>
          <surface>
            <contact>
              <ode/>
            </contact>
            <bounce/>
            <friction>
              <torsional>
                <ode/>
              </torsional>
              <ode/>
            </friction>
          </surface>
        </collision>
        <visual name='Stairs_0_Visual_6'>
          <pose frame=''>2.45797 -2.02275 1.08333 0 -0 0</pose>
          <geometry>
            <box>
              <size>1 0.233333 0.166667</size>
            </box>
          </geometry>
          <material>
            <script>
              <uri>file://media/materials/scripts/gazebo.material</uri>
              <name>Gazebo/Grey</name>
            </script>
            <ambient>1 1 1 1</ambient>
          </material>
          <meta>
            <layer>0</layer>
          </meta>
        </visual>
        <collision name='Stairs_0_Collision_6'>
          <geometry>
            <box>
              <size>1 0.233333 0.166667</size>
            </box>
          </geometry>
          <pose frame=''>2.45797 -2.02275 1.08333 0 -0 0</pose>
          <max_contacts>10</max_contacts>
          <surface>
            <contact>
              <ode/>
            </contact>
            <bounce/>
            <friction>
              <torsional>
                <ode/>
              </torsional>
              <ode/>
            </friction>
          </surface>
        </collision>
        <visual name='Stairs_0_Visual_7'>
          <pose frame=''>2.45797 -2.25609 1.25 0 -0 0</pose>
          <geometry>
            <box>
              <size>1 0.233333 0.166667</size>
            </box>
          </geometry>
          <material>
            <script>
              <uri>file://media/materials/scripts/gazebo.material</uri>
              <name>Gazebo/Grey</name>
            </script>
            <ambient>1 1 1 1</ambient>
          </material>
          <meta>
            <layer>0</layer>
          </meta>
        </visual>
        <collision name='Stairs_0_Collision_7'>
          <geometry>
            <box>
              <size>1 0.233333 0.166667</size>
            </box>
          </geometry>
          <pose frame=''>2.45797 -2.25609 1.25 0 -0 0</pose>
          <max_contacts>10</max_contacts>
          <surface>
            <contact>
              <ode/>
            </contact>
            <bounce/>
            <friction>
              <torsional>
                <ode/>
              </torsional>
              <ode/>
            </friction>
          </surface>
        </collision>
        <visual name='Stairs_0_Visual_8'>
          <pose frame=''>2.45797 -2.48942 1.41667 0 -0 0</pose>
          <geometry>
            <box>
              <size>1 0.233333 0.166667</size>
            </box>
          </geometry>
          <material>
            <script>
              <uri>file://media/materials/scripts/gazebo.material</uri>
              <name>Gazebo/Grey</name>
            </script>
            <ambient>1 1 1 1</ambient>
          </material>
          <meta>
            <layer>0</layer>
          </meta>
        </visual>
        <collision name='Stairs_0_Collision_8'>
          <geometry>
            <box>
              <size>1 0.233333 0.166667</size>
            </box>
          </geometry>
          <pose frame=''>2.45797 -2.48942 1.41667 0 -0 0</pose>
          <max_contacts>10</max_contacts>
          <surface>
            <contact>
              <ode/>
            </contact>
            <bounce/>
            <friction>
              <torsional>
                <ode/>
              </torsional>
              <ode/>
            </friction>
          </surface>
        </collision>
        <visual name='Stairs_0_Visual_9'>
          <pose frame=''>2.45797 -2.72275 1.58333 0 -0 0</pose>
          <geometry>
            <box>
              <size>1 0.233333 0.166667</size>
            </box>
          </geometry>
          <material>
            <script>
              <uri>file://media/materials/scripts/gazebo.material</uri>
              <name>Gazebo/Grey</name>
            </script>
            <ambient>1 1 1 1</ambient>
          </material>
          <meta>
            <layer>0</layer>
          </meta>
        </visual>
        <collision name='Stairs_0_Collision_9'>
          <geometry>
            <box>
              <size>1 0.233333 0.166667</size>
            </box>
          </geometry>
          <pose frame=''>2.45797 -2.72275 1.58333 0 -0 0</pose>
          <max_contacts>10</max_contacts>
          <surface>
            <contact>
              <ode/>
            </contact>
            <bounce/>
            <friction>
              <torsional>
                <ode/>
              </torsional>
              <ode/>
            </friction>
          </surface>
        </collision>
        <visual name='Stairs_0_Visual_10'>
          <pose frame=''>2.45797 -2.95608 1.75 0 -0 0</pose>
          <geometry>
            <box>
              <size>1 0.233333 0.166667</size>
            </box>
          </geometry>
          <material>
            <script>
              <uri>file://media/materials/scripts/gazebo.material</uri>
              <name>Gazebo/Grey</name>
            </script>
            <ambient>1 1 1 1</ambient>
          </material>
          <meta>
            <layer>0</layer>
          </meta>
        </visual>
        <collision name='Stairs_0_Collision_10'>
          <geometry>
            <box>
              <size>1 0.233333 0.166667</size>
            </box>
          </geometry>
          <pose frame=''>2.45797 -2.95608 1.75 0 -0 0</pose>
          <max_contacts>10</max_contacts>
          <surface>
            <contact>
              <ode/>
            </contact>
            <bounce/>
            <friction>
              <torsional>
                <ode/>
              </torsional>
              <ode/>
            </friction>
          </surface>
        </collision>
        <visual name='Stairs_0_Visual_11'>
          <pose frame=''>2.45797 -3.18942 1.91667 0 -0 0</pose>
          <geometry>
            <box>
              <size>1 0.233333 0.166667</size>
            </box>
          </geometry>
          <material>
            <script>
              <uri>file://media/materials/scripts/gazebo.material</uri>
              <name>Gazebo/Grey</name>
            </script>
            <ambient>1 1 1 1</ambient>
          </material>
          <meta>
            <layer>0</layer>
          </meta>
        </visual>
        <collision name='Stairs_0_Collision_11'>
          <geometry>
            <box>
              <size>1 0.233333 0.166667</size>
            </box>
          </geometry>
          <pose frame=''>2.45797 -3.18942 1.91667 0 -0 0</pose>
          <max_contacts>10</max_contacts>
          <surface>
            <contact>
              <ode/>
            </contact>
            <bounce/>
            <friction>
              <torsional>
                <ode/>
              </torsional>
              <ode/>
            </friction>
          </surface>
        </collision>
        <visual name='Stairs_0_Visual_12'>
          <pose frame=''>2.45797 -3.42275 2.08333 0 -0 0</pose>
          <geometry>
            <box>
              <size>1 0.233333 0.166667</size>
            </box>
          </geometry>
          <material>
            <script>
              <uri>file://media/materials/scripts/gazebo.material</uri>
              <name>Gazebo/Grey</name>
            </script>
            <ambient>1 1 1 1</ambient>
          </material>
          <meta>
            <layer>0</layer>
          </meta>
        </visual>
        <collision name='Stairs_0_Collision_12'>
          <geometry>
            <box>
              <size>1 0.233333 0.166667</size>
            </box>
          </geometry>
          <pose frame=''>2.45797 -3.42275 2.08333 0 -0 0</pose>
          <max_contacts>10</max_contacts>
          <surface>
            <contact>
              <ode/>
            </contact>
            <bounce/>
            <friction>
              <torsional>
                <ode/>
              </torsional>
              <ode/>
            </friction>
          </surface>
        </collision>
        <visual name='Stairs_0_Visual_13'>
          <pose frame=''>2.45797 -3.65609 2.25 0 -0 0</pose>
          <geometry>
            <box>
              <size>1 0.233333 0.166667</size>
            </box>
          </geometry>
          <material>
            <script>
              <uri>file://media/materials/scripts/gazebo.material</uri>
              <name>Gazebo/Grey</name>
            </script>
            <ambient>1 1 1 1</ambient>
          </material>
          <meta>
            <layer>0</layer>
          </meta>
        </visual>
        <collision name='Stairs_0_Collision_13'>
          <geometry>
            <box>
              <size>1 0.233333 0.166667</size>
            </box>
          </geometry>
          <pose frame=''>2.45797 -3.65609 2.25 0 -0 0</pose>
          <max_contacts>10</max_contacts>
          <surface>
            <contact>
              <ode/>
            </contact>
            <bounce/>
            <friction>
              <torsional>
                <ode/>
              </torsional>
              <ode/>
            </friction>
          </surface>
        </collision>
        <visual name='Stairs_0_Visual_14'>
          <pose frame=''>2.45797 -3.88942 2.41667 0 -0 0</pose>
          <geometry>
            <box>
              <size>1 0.233333 0.166667</size>
            </box>
          </geometry>
          <material>
            <script>
              <uri>file://media/materials/scripts/gazebo.material</uri>
              <name>Gazebo/Grey</name>
            </script>
            <ambient>1 1 1 1</ambient>
          </material>
          <meta>
            <layer>0</layer>
          </meta>
        </visual>
        <collision name='Stairs_0_Collision_14'>
          <geometry>
            <box>
              <size>1 0.233333 0.166667</size>
            </box>
          </geometry>
          <pose frame=''>2.45797 -3.88942 2.41667 0 -0 0</pose>
          <max_contacts>10</max_contacts>
          <surface>
            <contact>
              <ode/>
            </contact>
            <bounce/>
            <friction>
              <torsional>
                <ode/>
              </torsional>
              <ode/>
            </friction>
          </surface>
        </collision>
        <self_collide>0</self_collide>
        <kinematic>0</kinematic>
      </link>
      <link name='Wall_0'>
        <pose frame=''>0 -4.05 0 0 -0 3.14159</pose>
        <visual name='Wall_0_Visual_0'>
          <pose frame=''>-1.80618 0 1.25 0 -0 0</pose>
          <geometry>
            <box>
              <size>2.63764 0.15 2.5</size>
            </box>
          </geometry>
          <material>
            <script>
              <uri>file://media/materials/scripts/gazebo.material</uri>
              <name>Gazebo/CeilingTiled</name>
            </script>
            <ambient>1 1 1 1</ambient>
          </material>
          <meta>
            <layer>0</layer>
          </meta>
        </visual>
        <collision name='Wall_0_Collision_0'>
          <geometry>
            <box>
              <size>2.63764 0.15 2.5</size>
            </box>
          </geometry>
          <pose frame=''>-1.80618 0 1.25 0 -0 0</pose>
          <max_contacts>10</max_contacts>
          <surface>
            <contact>
              <ode/>
            </contact>
            <bounce/>
            <friction>
              <torsional>
                <ode/>
              </torsional>
              <ode/>
            </friction>
          </surface>
        </collision>
        <visual name='Wall_0_Visual_1'>
          <pose frame=''>1.76882 0 1.25 0 -0 0</pose>
          <geometry>
            <box>
              <size>2.71236 0.15 2.5</size>
            </box>
          </geometry>
          <material>
            <script>
              <uri>file://media/materials/scripts/gazebo.material</uri>
              <name>Gazebo/CeilingTiled</name>
            </script>
            <ambient>1 1 1 1</ambient>
          </material>
          <meta>
            <layer>0</layer>
          </meta>
        </visual>
        <collision name='Wall_0_Collision_1'>
          <geometry>
            <box>
              <size>2.71236 0.15 2.5</size>
            </box>
          </geometry>
          <pose frame=''>1.76882 0 1.25 0 -0 0</pose>
          <max_contacts>10</max_contacts>
          <surface>
            <contact>
              <ode/>
            </contact>
            <bounce/>
            <friction>
              <torsional>
                <ode/>
              </torsional>
              <ode/>
            </friction>
          </surface>
        </collision>
        <visual name='Wall_0_Visual_2'>
          <pose frame=''>-0.037357 0 2.25 0 -0 0</pose>
          <geometry>
            <box>
              <size>0.9 0.15 0.5</size>
            </box>
          </geometry>
          <material>
            <script>
              <uri>file://media/materials/scripts/gazebo.material</uri>
              <name>Gazebo/CeilingTiled</name>
            </script>
            <ambient>1 1 1 1</ambient>
          </material>
          <meta>
            <layer>0</layer>
          </meta>
        </visual>
        <collision name='Wall_0_Collision_2'>
          <geometry>
            <box>
              <size>0.9 0.15 0.5</size>
            </box>
          </geometry>
          <pose frame=''>-0.037357 0 2.25 0 -0 0</pose>
          <max_contacts>10</max_contacts>
          <surface>
            <contact>
              <ode/>
            </contact>
            <bounce/>
            <friction>
              <torsional>
                <ode/>
              </torsional>
              <ode/>
            </friction>
          </surface>
        </collision>
        <self_collide>0</self_collide>
        <kinematic>0</kinematic>
      </link>
      <link name='Wall_1'>
        <pose frame=''>-3.05 0 0 0 -0 1.5708</pose>
        <visual name='Wall_1_Visual_0'>
          <pose frame=''>-2.77874 0 1.25 0 -0 0</pose>
          <geometry>
            <box>
              <size>2.69252 0.15 2.5</size>
            </box>
          </geometry>
          <material>
            <script>
              <uri>file://media/materials/scripts/gazebo.material</uri>
              <name>Gazebo/CeilingTiled</name>
            </script>
            <ambient>1 1 1 1</ambient>
          </material>
          <meta>
            <layer>0</layer>
          </meta>
        </visual>
        <collision name='Wall_1_Collision_0'>
          <geometry>
            <box>
              <size>2.69252 0.15 2.5</size>
            </box>
          </geometry>
          <pose frame=''>-2.77874 0 1.25 0 -0 0</pose>
          <max_contacts>10</max_contacts>
          <surface>
            <contact>
              <ode/>
            </contact>
            <bounce/>
            <friction>
              <torsional>
                <ode/>
              </torsional>
              <ode/>
            </friction>
          </surface>
        </collision>
        <visual name='Wall_1_Visual_1'>
          <pose frame=''>1.34626 0 0.25 0 -0 0</pose>
          <geometry>
            <box>
              <size>5.55748 0.15 0.5</size>
            </box>
          </geometry>
          <material>
            <script>
              <uri>file://media/materials/scripts/gazebo.material</uri>
              <name>Gazebo/CeilingTiled</name>
            </script>
            <ambient>1 1 1 1</ambient>
          </material>
          <meta>
            <layer>0</layer>
          </meta>
        </visual>
        <collision name='Wall_1_Collision_1'>
          <geometry>
            <box>
              <size>5.55748 0.15 0.5</size>
            </box>
          </geometry>
          <pose frame=''>1.34626 0 0.25 0 -0 0</pose>
          <max_contacts>10</max_contacts>
          <surface>
            <contact>
              <ode/>
            </contact>
            <bounce/>
            <friction>
              <torsional>
                <ode/>
              </torsional>
              <ode/>
            </friction>
          </surface>
        </collision>
        <visual name='Wall_1_Visual_2'>
          <pose frame=''>0.497036 0 1.5 0 -0 0</pose>
          <geometry>
            <box>
              <size>2.25902 0.15 2</size>
            </box>
          </geometry>
          <material>
            <script>
              <uri>file://media/materials/scripts/gazebo.material</uri>
              <name>Gazebo/CeilingTiled</name>
            </script>
            <ambient>1 1 1 1</ambient>
          </material>
          <meta>
            <layer>0</layer>
          </meta>
        </visual>
        <collision name='Wall_1_Collision_2'>
          <geometry>
            <box>
              <size>2.25902 0.15 2</size>
            </box>
          </geometry>
          <pose frame=''>0.497036 0 1.5 0 -0 0</pose>
          <max_contacts>10</max_contacts>
          <surface>
            <contact>
              <ode/>
            </contact>
            <bounce/>
            <friction>
              <torsional>
                <ode/>
              </torsional>
              <ode/>
            </friction>
          </surface>
        </collision>
        <visual name='Wall_1_Visual_3'>
          <pose frame=''>3.27577 0 1.5 0 -0 0</pose>
          <geometry>
            <box>
              <size>1.69845 0.15 2</size>
            </box>
          </geometry>
          <material>
            <script>
              <uri>file://media/materials/scripts/gazebo.material</uri>
              <name>Gazebo/CeilingTiled</name>
            </script>
            <ambient>1 1 1 1</ambient>
          </material>
          <meta>
            <layer>0</layer>
          </meta>
        </visual>
        <collision name='Wall_1_Collision_3'>
          <geometry>
            <box>
              <size>1.69845 0.15 2</size>
            </box>
          </geometry>
          <pose frame=''>3.27577 0 1.5 0 -0 0</pose>
          <max_contacts>10</max_contacts>
          <surface>
            <contact>
              <ode/>
            </contact>
            <bounce/>
            <friction>
              <torsional>
                <ode/>
              </torsional>
              <ode/>
            </friction>
          </surface>
        </collision>
        <visual name='Wall_1_Visual_4'>
          <pose frame=''>-1.03248 0 1.9 0 -0 0</pose>
          <geometry>
            <box>
              <size>0.8 0.15 1.2</size>
            </box>
          </geometry>
          <material>
            <script>
              <uri>file://media/materials/scripts/gazebo.material</uri>
              <name>Gazebo/CeilingTiled</name>
            </script>
            <ambient>1 1 1 1</ambient>
          </material>
          <meta>
            <layer>0</layer>
          </meta>
        </visual>
        <collision name='Wall_1_Collision_4'>
          <geometry>
            <box>
              <size>0.8 0.15 1.2</size>
            </box>
          </geometry>
          <pose frame=''>-1.03248 0 1.9 0 -0 0</pose>
          <max_contacts>10</max_contacts>
          <surface>
            <contact>
              <ode/>
            </contact>
            <bounce/>
            <friction>
              <torsional>
                <ode/>
              </torsional>
              <ode/>
            </friction>
          </surface>
        </collision>
        <visual name='Wall_1_Visual_5'>
          <pose frame=''>2.02655 0 1.9 0 -0 0</pose>
          <geometry>
            <box>
              <size>0.8 0.15 1.2</size>
            </box>
          </geometry>
          <material>
            <script>
              <uri>file://media/materials/scripts/gazebo.material</uri>
              <name>Gazebo/CeilingTiled</name>
            </script>
            <ambient>1 1 1 1</ambient>
          </material>
          <meta>
            <layer>0</layer>
          </meta>
        </visual>
        <collision name='Wall_1_Collision_5'>
          <geometry>
            <box>
              <size>0.8 0.15 1.2</size>
            </box>
          </geometry>
          <pose frame=''>2.02655 0 1.9 0 -0 0</pose>
          <max_contacts>10</max_contacts>
          <surface>
            <contact>
              <ode/>
            </contact>
            <bounce/>
            <friction>
              <torsional>
                <ode/>
              </torsional>
              <ode/>
            </friction>
          </surface>
        </collision>
        <self_collide>0</self_collide>
        <kinematic>0</kinematic>
      </link>
      <link name='Wall_2'>
        <pose frame=''>0 4.05 0 0 -0 0</pose>
        <visual name='Wall_2_Visual_0'>
          <pose frame=''>-2.47533 0 1.25 0 -0 0</pose>
          <geometry>
            <box>
              <size>1.29935 0.15 2.5</size>
            </box>
          </geometry>
          <material>
            <script>
              <uri>file://media/materials/scripts/gazebo.material</uri>
              <name>Gazebo/CeilingTiled</name>
            </script>
            <ambient>1 1 1 1</ambient>
          </material>
          <meta>
            <layer>0</layer>
          </meta>
        </visual>
        <collision name='Wall_2_Collision_0'>
          <geometry>
            <box>
              <size>1.29935 0.15 2.5</size>
            </box>
          </geometry>
          <pose frame=''>-2.47533 0 1.25 0 -0 0</pose>
          <max_contacts>10</max_contacts>
          <surface>
            <contact>
              <ode/>
            </contact>
            <bounce/>
            <friction>
              <torsional>
                <ode/>
              </torsional>
              <ode/>
            </friction>
          </surface>
        </collision>
        <visual name='Wall_2_Visual_1'>
          <pose frame=''>0.649673 0 0.25 0 -0 0</pose>
          <geometry>
            <box>
              <size>4.95065 0.15 0.5</size>
            </box>
          </geometry>
          <material>
            <script>
              <uri>file://media/materials/scripts/gazebo.material</uri>
              <name>Gazebo/CeilingTiled</name>
            </script>
            <ambient>1 1 1 1</ambient>
          </material>
          <meta>
            <layer>0</layer>
          </meta>
        </visual>
        <collision name='Wall_2_Collision_1'>
          <geometry>
            <box>
              <size>4.95065 0.15 0.5</size>
            </box>
          </geometry>
          <pose frame=''>0.649673 0 0.25 0 -0 0</pose>
          <max_contacts>10</max_contacts>
          <surface>
            <contact>
              <ode/>
            </contact>
            <bounce/>
            <friction>
              <torsional>
                <ode/>
              </torsional>
              <ode/>
            </friction>
          </surface>
        </collision>
        <visual name='Wall_2_Visual_2'>
          <pose frame=''>-0.082344 0 1.5 0 -0 0</pose>
          <geometry>
            <box>
              <size>1.88662 0.15 2</size>
            </box>
          </geometry>
          <material>
            <script>
              <uri>file://media/materials/scripts/gazebo.material</uri>
              <name>Gazebo/CeilingTiled</name>
            </script>
            <ambient>1 1 1 1</ambient>
          </material>
          <meta>
            <layer>0</layer>
          </meta>
        </visual>
        <collision name='Wall_2_Collision_2'>
          <geometry>
            <box>
              <size>1.88662 0.15 2</size>
            </box>
          </geometry>
          <pose frame=''>-0.082344 0 1.5 0 -0 0</pose>
          <max_contacts>10</max_contacts>
          <surface>
            <contact>
              <ode/>
            </contact>
            <bounce/>
            <friction>
              <torsional>
                <ode/>
              </torsional>
              <ode/>
            </friction>
          </surface>
        </collision>
        <visual name='Wall_2_Visual_3'>
          <pose frame=''>2.39298 0 1.5 0 -0 0</pose>
          <geometry>
            <box>
              <size>1.46403 0.15 2</size>
            </box>
          </geometry>
          <material>
            <script>
              <uri>file://media/materials/scripts/gazebo.material</uri>
              <name>Gazebo/CeilingTiled</name>
            </script>
            <ambient>1 1 1 1</ambient>
          </material>
          <meta>
            <layer>0</layer>
          </meta>
        </visual>
        <collision name='Wall_2_Collision_3'>
          <geometry>
            <box>
              <size>1.46403 0.15 2</size>
            </box>
          </geometry>
          <pose frame=''>2.39298 0 1.5 0 -0 0</pose>
          <max_contacts>10</max_contacts>
          <surface>
            <contact>
              <ode/>
            </contact>
            <bounce/>
            <friction>
              <torsional>
                <ode/>
              </torsional>
              <ode/>
            </friction>
          </surface>
        </collision>
        <visual name='Wall_2_Visual_4'>
          <pose frame=''>-1.42565 0 1.9 0 -0 0</pose>
          <geometry>
            <box>
              <size>0.8 0.15 1.2</size>
            </box>
          </geometry>
          <material>
            <script>
              <uri>file://media/materials/scripts/gazebo.material</uri>
              <name>Gazebo/CeilingTiled</name>
            </script>
            <ambient>1 1 1 1</ambient>
          </material>
          <meta>
            <layer>0</layer>
          </meta>
        </visual>
        <collision name='Wall_2_Collision_4'>
          <geometry>
            <box>
              <size>0.8 0.15 1.2</size>
            </box>
          </geometry>
          <pose frame=''>-1.42565 0 1.9 0 -0 0</pose>
          <max_contacts>10</max_contacts>
          <surface>
            <contact>
              <ode/>
            </contact>
            <bounce/>
            <friction>
              <torsional>
                <ode/>
              </torsional>
              <ode/>
            </friction>
          </surface>
        </collision>
        <visual name='Wall_2_Visual_5'>
          <pose frame=''>1.26097 0 1.9 0 -0 0</pose>
          <geometry>
            <box>
              <size>0.8 0.15 1.2</size>
            </box>
          </geometry>
          <material>
            <script>
              <uri>file://media/materials/scripts/gazebo.material</uri>
              <name>Gazebo/CeilingTiled</name>
            </script>
            <ambient>1 1 1 1</ambient>
          </material>
          <meta>
            <layer>0</layer>
          </meta>
        </visual>
        <collision name='Wall_2_Collision_5'>
          <geometry>
            <box>
              <size>0.8 0.15 1.2</size>
            </box>
          </geometry>
          <pose frame=''>1.26097 0 1.9 0 -0 0</pose>
          <max_contacts>10</max_contacts>
          <surface>
            <contact>
              <ode/>
            </contact>
            <bounce/>
            <friction>
              <torsional>
                <ode/>
              </torsional>
              <ode/>
            </friction>
          </surface>
        </collision>
        <self_collide>0</self_collide>
        <kinematic>0</kinematic>
      </link>
      <link name='Wall_3'>
        <pose frame=''>3.05 0 0 0 0 -1.5708</pose>
        <visual name='Wall_3_Visual_0'>
          <pose frame=''>-3.20927 0 1.25 0 -0 0</pose>
          <geometry>
            <box>
              <size>1.83145 0.15 2.5</size>
            </box>
          </geometry>
          <material>
            <script>
              <uri>file://media/materials/scripts/gazebo.material</uri>
              <name>Gazebo/CeilingTiled</name>
            </script>
            <ambient>1 1 1 1</ambient>
          </material>
          <meta>
            <layer>0</layer>
          </meta>
        </visual>
        <collision name='Wall_3_Collision_0'>
          <geometry>
            <box>
              <size>1.83145 0.15 2.5</size>
            </box>
          </geometry>
          <pose frame=''>-3.20927 0 1.25 0 -0 0</pose>
          <max_contacts>10</max_contacts>
          <surface>
            <contact>
              <ode/>
            </contact>
            <bounce/>
            <friction>
              <torsional>
                <ode/>
              </torsional>
              <ode/>
            </friction>
          </surface>
        </collision>
        <visual name='Wall_3_Visual_1'>
          <pose frame=''>0.915727 0 0.25 0 -0 0</pose>
          <geometry>
            <box>
              <size>6.41855 0.15 0.5</size>
            </box>
          </geometry>
          <material>
            <script>
              <uri>file://media/materials/scripts/gazebo.material</uri>
              <name>Gazebo/CeilingTiled</name>
            </script>
            <ambient>1 1 1 1</ambient>
          </material>
          <meta>
            <layer>0</layer>
          </meta>
        </visual>
        <collision name='Wall_3_Collision_1'>
          <geometry>
            <box>
              <size>6.41855 0.15 0.5</size>
            </box>
          </geometry>
          <pose frame=''>0.915727 0 0.25 0 -0 0</pose>
          <max_contacts>10</max_contacts>
          <surface>
            <contact>
              <ode/>
            </contact>
            <bounce/>
            <friction>
              <torsional>
                <ode/>
              </torsional>
              <ode/>
            </friction>
          </surface>
        </collision>
        <visual name='Wall_3_Visual_2'>
          <pose frame=''>-0.350735 0 1.5 0 -0 0</pose>
          <geometry>
            <box>
              <size>2.28562 0.15 2</size>
            </box>
          </geometry>
          <material>
            <script>
              <uri>file://media/materials/scripts/gazebo.material</uri>
              <name>Gazebo/CeilingTiled</name>
            </script>
            <ambient>1 1 1 1</ambient>
          </material>
          <meta>
            <layer>0</layer>
          </meta>
        </visual>
        <collision name='Wall_3_Collision_2'>
          <geometry>
            <box>
              <size>2.28562 0.15 2</size>
            </box>
          </geometry>
          <pose frame=''>-0.350735 0 1.5 0 -0 0</pose>
          <max_contacts>10</max_contacts>
          <surface>
            <contact>
              <ode/>
            </contact>
            <bounce/>
            <friction>
              <torsional>
                <ode/>
              </torsional>
              <ode/>
            </friction>
          </surface>
        </collision>
        <visual name='Wall_3_Visual_3'>
          <pose frame=''>2.85854 0 1.5 0 -0 0</pose>
          <geometry>
            <box>
              <size>2.53292 0.15 2</size>
            </box>
          </geometry>
          <material>
            <script>
              <uri>file://media/materials/scripts/gazebo.material</uri>
              <name>Gazebo/CeilingTiled</name>
            </script>
            <ambient>1 1 1 1</ambient>
          </material>
          <meta>
            <layer>0</layer>
          </meta>
        </visual>
        <collision name='Wall_3_Collision_3'>
          <geometry>
            <box>
              <size>2.53292 0.15 2</size>
            </box>
          </geometry>
          <pose frame=''>2.85854 0 1.5 0 -0 0</pose>
          <max_contacts>10</max_contacts>
          <surface>
            <contact>
              <ode/>
            </contact>
            <bounce/>
            <friction>
              <torsional>
                <ode/>
              </torsional>
              <ode/>
            </friction>
          </surface>
        </collision>
        <visual name='Wall_3_Visual_4'>
          <pose frame=''>-1.89355 0 1.9 0 -0 0</pose>
          <geometry>
            <box>
              <size>0.8 0.15 1.2</size>
            </box>
          </geometry>
          <material>
            <script>
              <uri>file://media/materials/scripts/gazebo.material</uri>
              <name>Gazebo/CeilingTiled</name>
            </script>
            <ambient>1 1 1 1</ambient>
          </material>
          <meta>
            <layer>0</layer>
          </meta>
        </visual>
        <collision name='Wall_3_Collision_4'>
          <geometry>
            <box>
              <size>0.8 0.15 1.2</size>
            </box>
          </geometry>
          <pose frame=''>-1.89355 0 1.9 0 -0 0</pose>
          <max_contacts>10</max_contacts>
          <surface>
            <contact>
              <ode/>
            </contact>
            <bounce/>
            <friction>
              <torsional>
                <ode/>
              </torsional>
              <ode/>
            </friction>
          </surface>
        </collision>
        <visual name='Wall_3_Visual_5'>
          <pose frame=''>1.19208 0 1.9 0 -0 0</pose>
          <geometry>
            <box>
              <size>0.8 0.15 1.2</size>
            </box>
          </geometry>
          <material>
            <script>
              <uri>file://media/materials/scripts/gazebo.material</uri>
              <name>Gazebo/CeilingTiled</name>
            </script>
            <ambient>1 1 1 1</ambient>
          </material>
          <meta>
            <layer>0</layer>
          </meta>
        </visual>
        <collision name='Wall_3_Collision_5'>
          <geometry>
            <box>
              <size>0.8 0.15 1.2</size>
            </box>
          </geometry>
          <pose frame=''>1.19208 0 1.9 0 -0 0</pose>
          <max_contacts>10</max_contacts>
          <surface>
            <contact>
              <ode/>
            </contact>
            <bounce/>
            <friction>
              <torsional>
                <ode/>
              </torsional>
              <ode/>
            </friction>
          </surface>
        </collision>
        <self_collide>0</self_collide>
        <kinematic>0</kinematic>
      </link>
      <static>1</static>
    </model>
    <model name='bowl_0'>
      <static>1</static>
      <link name='link'>
        <inertial>
          <pose frame=''>0 0 0.0175 0 -0 0</pose>
          <mass>0.1</mass>
          <inertia>
            <ixx>0.000250308</ixx>
            <ixy>0</ixy>
            <ixz>0</ixz>
            <iyy>0.000250308</iyy>
            <iyz>0</iyz>
            <izz>0.0004802</izz>
          </inertia>
        </inertial>
        <collision name='collision'>
          <pose frame=''>0 0 0.0175 0 -0 0</pose>
          <geometry>
            <cylinder>
              <radius>0.098</radius>
              <length>0.035</length>
            </cylinder>
          </geometry>
          <max_contacts>10</max_contacts>
          <surface>
            <contact>
              <ode/>
            </contact>
            <bounce/>
            <friction>
              <torsional>
                <ode/>
              </torsional>
              <ode/>
            </friction>
          </surface>
        </collision>
        <visual name='visual'>
          <geometry>
            <mesh>
              <uri>model://bowl/meshes/bowl.dae</uri>
            </mesh>
          </geometry>
          <material>
            <script>
              <uri>file://media/materials/scripts/gazebo.material</uri>
              <name>Gazebo/Red</name>
            </script>
          </material>
        </visual>
        <self_collide>0</self_collide>
        <kinematic>0</kinematic>
      </link>
      <pose frame=''>-0.03 0.85 0.73 0 -0 0</pose>
    </model>
    <state world_name='default'>
      <sim_time>379 392000000</sim_time>
      <real_time>392 377383449</real_time>
      <wall_time>1587130811 705968179</wall_time>
      <iterations>379392</iterations>
      <model name='ground_plane'>
        <pose frame=''>0 0 0 0 -0 0</pose>
        <scale>1 1 1</scale>
        <link name='link'>
          <pose frame=''>0 0 0 0 -0 0</pose>
          <velocity>0 0 0 0 -0 0</velocity>
          <acceleration>0 0 0 0 -0 0</acceleration>
          <wrench>0 0 0 0 -0 0</wrench>
        </link>
      </model>
      <model name='home'>
        <pose frame=''>0.349793 0.122852 0 0 -0 0</pose>
        <scale>1 1 1</scale>
        <link name='Stairs_0'>
          <pose frame=''>0.349793 0.122852 0 0 -0 0</pose>
          <velocity>0 0 0 0 -0 0</velocity>
          <acceleration>0 0 0 0 -0 0</acceleration>
          <wrench>0 0 0 0 -0 0</wrench>
        </link>
        <link name='Wall_0'>
          <pose frame=''>0.349793 -3.92715 0 0 -0 3.14159</pose>
          <velocity>0 0 0 0 -0 0</velocity>
          <acceleration>0 0 0 0 -0 0</acceleration>
          <wrench>0 0 0 0 -0 0</wrench>
        </link>
        <link name='Wall_1'>
          <pose frame=''>-2.70021 0.122852 0 0 -0 1.5708</pose>
          <velocity>0 0 0 0 -0 0</velocity>
          <acceleration>0 0 0 0 -0 0</acceleration>
          <wrench>0 0 0 0 -0 0</wrench>
        </link>
        <link name='Wall_2'>
          <pose frame=''>0.349793 4.17285 0 0 -0 0</pose>
          <velocity>0 0 0 0 -0 0</velocity>
          <acceleration>0 0 0 0 -0 0</acceleration>
          <wrench>0 0 0 0 -0 0</wrench>
        </link>
        <link name='Wall_3'>
          <pose frame=''>3.39979 0.122852 0 0 0 -1.5708</pose>
          <velocity>0 0 0 0 -0 0</velocity>
          <acceleration>0 0 0 0 -0 0</acceleration>
          <wrench>0 0 0 0 -0 0</wrench>
        </link>
      </model>
      <model name='human'>
        <pose frame=''>-0.09 1.29 -1.3 0 -0 0</pose>
        <scale>1 1 1</scale>
        <link name='body'>
          <pose frame=''>-0.09 1.29 -1.3 0 -0 0</pose>
          <velocity>0 0 0 0 -0 0</velocity>
          <acceleration>0 0 0 0 -0 0</acceleration>
          <wrench>0 0 0 0 -0 0</wrench>
        </link>
      </model>
      <model name='j2n6s300'>
        <pose frame=''>-3.4e-05 6e-06 5e-06 6e-06 4e-05 0</pose>
        <scale>1 1 1</scale>
        <link name='j2n6s300_link_1'>
          <pose frame=''>0.299995 1.05 0.90675 -3.14158 8.1e-05 -3.14156</pose>
          <velocity>-0.001542 0.00027 0.000196 -0.003682 -0.024699 0.00653</velocity>
          <acceleration>-4.80389 -0.121303 0.257891 -2.37211 -1.50297 -2.24571</acceleration>
          <wrench>-3.59187 -0.090698 0.192825 0 -0 0</wrench>
        </link>
        <link name='j2n6s300_link_2'>
          <pose frame=''>0.299982 1.0516 1.02551 1.57075 -0.88621 7.3e-05</pose>
          <velocity>-0.005578 0.001162 0.001799 -0.011743 -0.018745 0.007512</velocity>
          <acceleration>1.69701 3.20148 15.7095 -3.07628 -0.017385 -1.69244</acceleration>
          <wrench>1.68004 3.16947 15.5524 0 -0 0</wrench>
        </link>
        <link name='j2n6s300_link_3'>
          <pose frame=''>0.617602 1.05161 0.766239 1.57089 0.554701 -3.14147</pose>
          <velocity>0.000632 0.002123 0.00849 -0.022061 0.002526 0.01822</velocity>
          <acceleration>7.41913 5.73337 24.906 1.42646 -0.468607 -1.2092</acceleration>
          <wrench>5.01756 3.87748 16.844 0 -0 0</wrench>
        </link>
        <link name='j2n6s300_link_4'>
          <pose frame=''>0.50843 1.04022 0.94241 2.64506 0.258022 2.01076</pose>
          <velocity>0.003253 0.005713 0.006711 0.126337 0.013022 -0.22935</velocity>
          <acceleration>-3.63305 -1.53739 8.40312 0.498722 -1.49441 2.45778</acceleration>
          <wrench>-1.54901 -0.655493 3.58281 0 -0 0</wrench>
        </link>
        <link name='j2n6s300_link_5'>
          <pose frame=''>0.447152 1.02227 0.979881 -1.63383 1.14303 -1.19499</pose>
          <velocity>0.004415 0.013181 0.006023 0.19241 0.048099 -0.219751</velocity>
          <acceleration>4.35509 -8.53364 3.5169 2.49577 0.061833 3.06687</acceleration>
          <wrench>1.85686 -3.63846 1.49949 0 -0 0</wrench>
        </link>
        <link name='j2n6s300_link_6'>
          <pose frame=''>0.403473 0.964937 0.99689 2.68093 -1.14285 1.94701</pose>
          <velocity>-0.006858 0.019663 -0.002775 0.182582 0.053864 -0.188565</velocity>
          <acceleration>11.4376 -10.5511 0.642532 -0.758901 -1.13453 -0.685612</acceleration>
          <wrench>11.3233 -10.4456 0.636106 0 -0 0</wrench>
        </link>
        <link name='j2n6s300_link_finger_1'>
          <pose frame=''>0.420651 0.858898 1.04784 -2.74666 -0.397699 -1.6514</pose>
          <velocity>-0.020389 0.007801 -0.020164 0.897064 -0.719879 -1.89863</velocity>
          <acceleration>8.41251 -13.8936 -14.5423 1.53984 1.00288 0.220534</acceleration>
          <wrench>0.084125 -0.138936 -0.145423 0 -0 0</wrench>
        </link>
        <link name='j2n6s300_link_finger_2'>
          <pose frame=''>0.360437 0.869028 1.05485 0.273742 -0.269374 -2.46568</pose>
          <velocity>-0.021753 0.017623 -0.01809 0.166779 -0.133043 -0.651145</velocity>
          <acceleration>6.84068 -1.48973 1.52138 -0.252954 -0.022543 -0.06152</acceleration>
          <wrench>0.068407 -0.014897 0.015214 0 -0 0</wrench>
        </link>
        <link name='j2n6s300_link_finger_3'>
          <pose frame=''>0.367194 0.851877 1.01433 0.532231 0.053166 -2.52624</pose>
          <velocity>-0.02366 0.016006 -0.020564 0.317564 -0.097587 -0.595301</velocity>
          <acceleration>16.728 -26.0651 7.80399 -0.250874 -1.42076 0.056224</acceleration>
          <wrench>0.16728 -0.260651 0.07804 0 -0 0</wrench>
        </link>
        <link name='j2n6s300_link_finger_tip_1'>
          <pose frame=''>0.420194 0.818719 1.06596 -2.90549 0.504934 2.7739</pose>
          <velocity>-0.10188 0.000799 -0.055315 0.792942 -0.610501 -1.65091</velocity>
          <acceleration>-0.028425 -5.81456 -19.163 -0.243251 1.50675 2.25503</acceleration>
          <wrench>-0.000284 -0.058146 -0.19163 0 -0 0</wrench>
        </link>
        <link name='j2n6s300_link_finger_tip_2'>
          <pose frame=''>0.32539 0.844623 1.06577 0.183128 -0.336517 -2.16434</pose>
          <velocity>-0.040269 0.039034 -0.026853 0.206509 0.351957 0.560135</velocity>
          <acceleration>-0.973675 7.38503 1.56599 1.38044 0.562919 0.705196</acceleration>
          <wrench>-0.009737 0.07385 0.01566 0 -0 0</wrench>
        </link>
        <link name='j2n6s300_link_finger_tip_3'>
          <pose frame=''>0.32989 0.828712 1.01046 0.532853 0.045049 -2.51326</pose>
          <velocity>-0.035089 0.032978 -0.03137 0.348222 -0.155284 -0.573323</velocity>
          <acceleration>-15.5184 2.55707 -15.3511 1.15694 1.43225 1.81888</acceleration>
          <wrench>-0.155184 0.025571 -0.153511 0 -0 0</wrench>
        </link>
        <link name='root'>
          <pose frame=''>0.299996 1.05 0.75 6e-06 4e-05 0</pose>
          <velocity>-0.001346 0.000271 -0.000108 0.002155 0.01205 0</velocity>
          <acceleration>0.2609 0.006222 -0.152603 -0.393154 0.374604 -0.000477</acceleration>
          <wrench>0.122059 0.002911 -0.071394 0 -0 0</wrench>
        </link>
      </model>
      <model name='table'>
        <pose frame=''>-0.08 0.78 -0.29 0 -0 0</pose>
        <scale>1 1 1</scale>
        <link name='table'>
          <pose frame=''>-0.08 0.78 -0.29 0 -0 0</pose>
          <velocity>0 0 0 0 -0 0</velocity>
          <acceleration>0 0 0 0 -0 0</acceleration>
          <wrench>0 0 0 0 -0 0</wrench>
        </link>
      </model>
      <light name='some_light'>
        <pose frame=''>0.072547 -1.53894 1.05221 0.199665 -0 -2.15086</pose>
      </light>
    </state>
  </world>
</sdf>
